Workbook

Sheet Summary
I4: Cumulative Extraction Summary by Method
I5: (time measured in seconds)
J6: Excel (Advanced) | K6: LLM API | L6: Python | V6: Standardization Goal
I7: Ticker | J7: Manual | K7: Presentation (exc build) | L7: Script (exc build)
B8: =K8/$J8-1 -> -0.29276316 | C8: =L8/$J8-1 -> 0.22368421 | I8: BAC | J8: =L30 -> 304 | K8: =Y30 -> 215 | L8: =AD30 -> 372
B9: =K9/$J9-1 -> -0.1807598 | C9: =L9/$J9-1 -> 0.62198529 | I9: WFC | J9: =L43 -> 544 | K9: =Y43 -> 445.66667 | L9: =AD43 -> 882.36
B10: =K10/$J10-1 -> -0.20121951 | C10: =L10/$J10-1 -> -0.67886179 | I10: JPM | J10: =L58 -> 492 | K10: =Y58 -> 393 | L10: =AD58 -> 158 | AH10: Scroll
B11: =K11/$J11-1 -> -0.31923077 | C11: =L11/$J11-1 -> -0.35128205 | I11: PNC | J11: =L75 -> 260 | K11: =Y75 -> 177 | L11: =AD75 -> 168.66667 | AH11: Right
B12: =K12/$J12-1 -> -0.60123043 | C12: =L12/$J12-1 -> -0.71029083 | I12: KEY | J12: =L91 -> 596 | K12: =Y91 -> 237.66667 | L12: =AD91 -> 172.66667 | AH12: for
B13: =K13/$J13-1 -> -0.55357143 | C13: =L13/$J13-1 -> 0.31994048 | I13: HBAN | J13: =L109 -> 224 | K13: =Y109 -> 100 | L13: =AD109 -> 295.66667 | AH13: Charts
B14: =K14/$J14-1 -> -0.75707547 | C14: =L14/$J14-1 -> -0.66273585 | I14: CFG | J14: =L127 -> 424 | K14: =Y127 -> 103 | L14: =AD127 -> 143
B15: =K15/$J15-1 -> -0.68465909 | C15: =L15/$J15-1 -> -0.58617424 | I15: FCNCA | J15: =L143 -> 352 | K15: =Y143 -> 111 | L15: =AD143 -> 145.66667
B16: =K16/$J16-1 -> -0.75 | C16: =L16/$J16-1 -> 0.011299435 | I16: SNV | J16: =L163 -> 472 | K16: =Y163 -> 118 | L16: =AD163 -> 477.33333
B17: =K17/$J17-1 -> -0.45661157 | C17: =L17/$J17-1 -> -0.2977135 | I17: RF | J17: =L184 -> 484 | K17: =Y184 -> 263 | L17: =AD184 -> 339.90667
B19: =K19/$J19-1 -> -0.47896596 | C19: =L19/$J19-1 -> -0.24006101 | G19: =AVERAGE(G30,G43,G58,G75,G91,G109,G127,G143,G163,G184) -> 640.8 | I19: Average | J19: =AVERAGE(J8:J17) -> 415.2 | K19: =AVERAGE(K8:K17) -> 216.33333 | L19: =AVERAGE(L8:L17) -> 315.52667
I20: Efficency | K20: =($J$19-K19)/$J$19 -> 0.47896596 | L20: =($J$19-L19)/$J$19 -> 0.24006101
AU22: Cumulative Time (10-Q) | BI22: Cumulative Time (10-Q)
D23: Excel (Manual - Presentation / 10-Q) | I23: Advanced Excel Manual Benchmark (10-Q) | N23: LLM Interface (Presentation) | U23: LLM API (Presentation) | AA23: Python Modules (10-Q) | AG23: Time Savings | AU23: (Python Modules vs Advanced Excel) | BI23: LLM API vs Advanced Excel | BW23: Script Construct | BZ23: LLM API Construct
I24: (time measured in seconds) | N24: Convert Prompt | P24: Correct Prompt | Q24: Standardization Prompt | R24: Clean Prompts | U24: (time measured in seconds) | AA24: (time measured in seconds) | BW24: Breakeven | BZ24: Breakeven
B25: Ticker | C25: Quarter | D25: Extraction | E25: Standardization | F25: Database Format | G25: Total Excel | I25: Extraction | J25: Standardization | K25: Database Format | L25: Total | N25: Extraction | O25: Accuracy | P25: Correction | Q25: Standardization | R25: Database Format | S25: Total LLM | U25: Construct Extraction | V25: Adjustment | W25: Execute | X25: Accuracy | Y25: Total | AA25: Construct Extraction | AB25: Adjustment | AC25: Execute | AD25: Total | AF25: Date | AG25: LLM API | AH25: Python Modules | AU25: Advanced Excel | AV25: Python Modules | AX25: Delta | AY25: Efficiency % | BI25: Advanced Excel | BJ25: LLM API | BL25: Delta | BM25: Efficiency %
B26: BAC | C26: 4Q24 | D26: 33 | E26: 0 | F26: 59 | G26: =SUM(D26:F26) -> 92 | I26: 30 | J26: 0 | K26: 46 | L26: =SUM(I26:K26) -> 76 | N26: =42+39 -> 81 | O26: ='BAC LLM Interface'!T23 -> 0.9 | P26: =N26+52+20 -> 153 | Q26: 0 | R26: =66+32+57+38+37+33+55+12 -> 330 | S26: =SUM(N26,P26,Q26,R26) -> 564 | V26: 37 | W26: 19 | X26: ='BAC LLM API'!F42 -> 0.7 | Y26: =SUM(U26:W26) -> 56 | AB26: 62 | AC26: 28 | AD26: =SUM(AA26:AC26) -> 90 | AF26: 45657 | AG26: =L26-Y26 -> 20 | AH26: =L26-AD26 -> -14 | AT26: 45657 | AU26: =L26+L27+L28+L29 -> 304 | AV26: =AD26+AD27+AD28+AD29 -> 372 | AX26: =AV26-AU26 -> 68 | AY26: =(-AX26/AU26) -> -0.22368421 | BH26: 45657 | BI26: =AU26 -> 304 | BJ26: =Y27+Y28+Y26+Y29 -> 215 | BL26: =BJ26-BI26 -> -89 | BM26: =(-BL26/BI26) -> 0.29276316 | BU26: =B26 -> BAC | BV26: 45657 | BW26: =L26-AD26 -> -14 | BZ26: =L26-Y26 -> 20
A27: Base | B27: BAC | C27: 3Q24 | D27: 33 | E27: 0 | F27: 59 | G27: =SUM(D27:F27) -> 92 | I27: 30 | J27: 0 | K27: 46 | L27: =SUM(I27:K27) -> 76 | N27: =42+26 -> 68 | O27: ='BAC LLM Interface'!T52 -> 0.9 | P27: =N27+52+15 -> 135 | Q27: 0 | R27: =66+17+57+15+37+28+55+9 -> 284 | S27: =SUM(N27,P27,Q27,R27) -> 487 | U27: =2727/250*60 -> 654.48 | V27: 0 | W27: 20 | X27: ='BAC LLM API'!F83 -> 0.9 | Y27: =W27+AVERAGE(V26,V28:V29) -> 55 | AA27: =1680/250*60 -> 403.2 | AB27: 0 | AC27: 32 | AD27: =AC27+AVERAGE(AB26,AB28:AB29) -> 97 | AF27: 45565 | AG27: =L27-Y27 -> 21 | AH27: =L27-AD27 -> -21 | AT27: 45565 | AU27: =L27+L28+L29 -> 228 | AV27: =AD27+AD28+AD29 -> 282 | AX27: =AV27-AU27 -> 54 | AY27: =(-AX27/AU27) -> -0.23684211 | BH27: 45565 | BI27: =AU27 -> 228 | BJ27: =Y28+Y29+Y27 -> 159 | BL27: =BJ27-BI27 -> -69 | BM27: =(-BL27/BI27) -> 0.30263158 | BU27: =B27 -> BAC | BV27: 45565 | BW27: =L27-(AC27+AVERAGE(AB26,AB28:AB29)) -> -21 | BZ27: =L27-(W27+AVERAGE(V26,V28:V29)) -> 21
B28: BAC | C28: 2Q24 | D28: 33 | E28: 0 | F28: 59 | G28: =SUM(D28:F28) -> 92 | I28: 30 | J28: 0 | K28: 46 | L28: =SUM(I28:K28) -> 76 | N28: =42+27 -> 69 | O28: ='BAC LLM Interface'!T83 -> 1 | P28: 0 | Q28: 0 | R28: =66+14+57+20+37+30+55+11 -> 290 | S28: =SUM(N28,P28,Q28,R28) -> 359 | V28: 34 | W28: 19 | X28: ='BAC LLM API'!F120 -> 1 | Y28: =SUM(U28:W28) -> 53 | AB28: 49 | AC28: 25 | AD28: =SUM(AA28:AC28) -> 74 | AF28: 45473 | AG28: =L28-Y28 -> 23 | AH28: =L28-AD28 -> 2 | AT28: 45473 | AU28: =L28+L29 -> 152 | AV28: =AD28+AD29 -> 185 | AX28: =AV28-AU28 -> 33 | AY28: =(-AX28/AU28) -> -0.21710526 | BH28: 45473 | BI28: =AU28 -> 152 | BJ28: =Y28+Y29 -> 104 | BL28: =BJ28-BI28 -> -48 | BM28: =(-BL28/BI28) -> 0.31578947 | BU28: =B28 -> BAC | BV28: 45473 | BW28: =L28-AD28 -> 2 | BZ28: =L28-Y28 -> 23
B29: BAC | C29: 1Q24 | D29: 33 | E29: 0 | F29: 59 | G29: =SUM(D29:F29) -> 92 | I29: 30 | J29: 0 | K29: 46 | L29: =SUM(I29:K29) -> 76 | N29: =42+42 -> 84 | O29: ='BAC LLM Interface'!T109 -> 1 | P29: 0 | Q29: 0 | R29: =66+11+57+20+37+29+55+26 -> 301 | S29: =SUM(N29,P29,Q29,R29) -> 385 | V29: 34 | W29: 17 | X29: ='BAC LLM API'!F158 -> 1 | Y29: =SUM(U29:W29) -> 51 | AB29: 84 | AC29: 27 | AD29: =SUM(AA29:AC29) -> 111 | AF29: 45382 | AG29: =L29-Y29 -> 25 | AH29: =L29-AD29 -> -35 | AT29: 45382 | AU29: =L29 -> 76 | AV29: =AD29 -> 111 | AX29: =AV29-AU29 -> 35 | AY29: =(-AX29/AU29) -> -0.46052632 | BH29: 45382 | BI29: =AU29 -> 76 | BJ29: =Y29 -> 51 | BL29: =BJ29-BI29 -> -25 | BM29: =(-BL29/BI29) -> 0.32894737 | BU29: =B29 -> BAC | BV29: 45382 | BW29: =L29-AD29 -> -35 | BZ29: =L29-Y29 -> 25
B30: Total | G30: =SUM(G26:G29) -> 368 | K30: Cumulative Total | L30: =SUM(L26:L29) -> 304 | S30: =SUM(S26:S29) -> 1795 | W30: Cumulative Total | Y30: =SUM(Y26:Y29) -> 215 | AC30: Cumulative Total | AD30: =SUM(AD26:AD29) -> 372 | AF30: Total | AG30: =SUM(AG26:AG29) -> 89 | AH30: =SUM(AH26:AH29) -> -68 | BV30: Quarter Breakeven | BW30: =AA27/AVERAGE(BW26:BX29) -> -23.717647 | BZ30: =U27/AVERAGE(BZ26:CA29) -> 29.414831
R31: Cumulative Efficiency % | S31: =(($L30-S30)/$L30)*1 -> -4.9046053 | W31: Cumulative Efficiency % | Y31: =($L30-Y30)/$L30*100% -> 0.29276316 | AC31: Cumulative Efficiency % | AD31: =($L30-AD30)/$L30*100% -> -0.22368421
W32: Average Accuracy | X32: =AVERAGE(X26:X29) -> 0.9
AB33: =AVERAGE(AB28:AB29,AB26) -> 65 | AC33: =AVERAGE(AC26:AC29) -> 28
D36: Excel (Manual - Presentation / 10-Q) | I36: Advanced Excel Manual Benchmark (10-Q) | N36: LLM (10-Q) | U36: LLM API (Presentation) | AA36: Python Modules (10-Q)
I37: (time measured in seconds) | N37: Convert Prompt | P37: Correct Prompt | Q37: Standardization Prompt | R37: Clean Prompts | U37: (time measured in seconds) | AA37: (time measured in seconds)
B38: Ticker | C38: Quarter | D38: Extraction | E38: Standardization | F38: Database Format | G38: Total Excel | I38: Extraction | J38: Standardization | K38: Database Format | L38: Total | N38: Extraction | O38: Accuracy | P38: Correction | Q38: Standardization | R38: Database Format | S38: Total LLM | U38: Construct Extraction | V38: Adjustment | W38: Execute | X38: Accuracy | Y38: Total | AA38: Construct Extraction | AB38: Adjustment | AC38: Execute | AD38: Total | AF38: Date | AG38: LLM API | AH38: Python Modules | AU38: Advanced Excel | AV38: Python Modules | AX38: Delta | AY38: Efficiency % | BI38: Advanced Excel | BJ38: LLM API | BL38: Delta | BM38: Efficiency %
B39: WFC | C39: 4Q24 | D39: 138 | E39: 52 | F39: 60 | G39: =SUM(D39:F39) -> 250 | I39: 52 | J39: 54 | K39: 30 | L39: =SUM(I39:K39) -> 136 | N39: =49+17 -> 66 | O39: ='WFC LLM Interface'!M27 -> 0.92307692 | P39: =52+12 -> 64 | Q39: =41+11 -> 52 | R39: =87+12+54+15+56+11 -> 235 | S39: =SUM(N39,P39,Q39,R39) -> 417 | V39: 85 | W39: 24 | X39: ='WFC LLM API'!F46 -> 0.83333333 | Y39: =SUM(U39:W39) -> 109 | AB39: =666/250*60+40 -> 199.84 | AC39: 25 | AD39: =SUM(AA39:AC39) -> 224.84 | AF39: 45657 | AG39: =L39-Y39 -> 27 | AH39: =L39-AD39 -> -88.84 | AT39: 45657 | AU39: =L39+L40+L41+L42 -> 544 | AV39: =AD39+AD40+AD41+AD42 -> 882.36 | AX39: =AV39-AU39 -> 338.36 | AY39: =(-AX39/AU39) -> -0.62198529 | BH39: 45657 | BI39: =AU39 -> 544 | BJ39: =Y40+Y41+Y39+Y42 -> 445.66667 | BL39: =BJ39-BI39 -> -98.333333 | BM39: =(-BL39/BI39) -> 0.1807598 | BU39: =B39 -> WFC | BV39: 45657 | BW39: =L39-AD39 -> -88.84 | BZ39: =L39-Y39 -> 27
A40: Base | B40: WFC | C40: 3Q24 | D40: 138 | E40: 52 | F40: 60 | G40: =SUM(D40:F40) -> 250 | I40: 52 | J40: 54 | K40: 30 | L40: =SUM(I40:K40) -> 136 | N40: =49+20 -> 69 | O40: ='WFC LLM Interface'!M59 -> 0.96153846 | P40: =29+16 -> 45 | Q40: =34+28 -> 62 | R40: =87+9+54+10+56+15 -> 231 | S40: =SUM(N40,P40,Q40,R40) -> 407 | U40: =2921/250*60 -> 701.04 | V40: 0 | W40: 33 | X40: ='WFC LLM API'!F95 -> 0.85 | Y40: =W40+AVERAGE(V39,V41:V42) -> 112.66667 | AA40: =(2334/250)*60+(1686/250)*60 -> 964.8 | AB40: 0 | AC40: 40 | AD40: =AC40+AVERAGE(AB39,AB41:AB42) -> 232.84 | AF40: 45565 | AG40: =L40-Y40 -> 23.333333 | AH40: =L40-AD40 -> -96.84 | AT40: 45565 | AU40: =L40+L41+L42 -> 408 | AV40: =AD40+AD41+AD42 -> 657.52 | AX40: =AV40-AU40 -> 249.52 | AY40: =(-AX40/AU40) -> -0.61156863 | BH40: 45565 | BI40: =AU40 -> 408 | BJ40: =Y41+Y42+Y40 -> 336.66667 | BL40: =BJ40-BI40 -> -71.333333 | BM40: =(-BL40/BI40) -> 0.1748366 | BU40: =B40 -> WFC | BV40: 45565 | BW40: =L40-(AC40+AVERAGE(AB39,AB41:AB42)) -> -96.84 | BZ40: =L40-(W40+AVERAGE(V39,V41:V42)) -> 23.333333
B41: WFC | C41: 2Q24 | D41: 138 | E41: 52 | F41: 60 | G41: =SUM(D41:F41) -> 250 | I41: 52 | J41: 54 | K41: 30 | L41: =SUM(I41:K41) -> 136 | N41: =49+20 -> 69 | O41: ='WFC LLM Interface'!M91 -> 0.92307692 | P41: =50+11 -> 61 | Q41: =34+10 -> 44 | R41: =87+10+54+19+56+13 -> 239 | S41: =SUM(N41,P41,Q41,R41) -> 413 | V41: 74 | W41: 31 | X41: ='WFC LLM API'!F142 -> 0.8 | Y41: =SUM(U41:W41) -> 105 | AB41: =666/250*60+29 -> 188.84 | AC41: 25 | AD41: =SUM(AA41:AC41) -> 213.84 | AF41: 45473 | AG41: =L41-Y41 -> 31 | AH41: =L41-AD41 -> -77.84 | AT41: 45473 | AU41: =L41+L42 -> 272 | AV41: =AD41+AD42 -> 424.68 | AX41: =AV41-AU41 -> 152.68 | AY41: =(-AX41/AU41) -> -0.56132353 | BH41: 45473 | BI41: =AU41 -> 272 | BJ41: =Y41+Y42 -> 224 | BL41: =BJ41-BI41 -> -48 | BM41: =(-BL41/BI41) -> 0.17647059 | BU41: =B41 -> WFC | BV41: 45473 | BW41: =L41-AD41 -> -77.84 | BZ41: =L41-Y41 -> 31
B42: WFC | C42: 1Q24 | D42: 138 | E42: 52 | F42: 60 | G42: =SUM(D42:F42) -> 250 | I42: 52 | J42: 54 | K42: 30 | L42: =SUM(I42:K42) -> 136 | N42: =49+13 -> 62 | O42: ='WFC LLM Interface'!M118 -> 0.92307692 | P42: =48+15 -> 63 | Q42: =34+12 -> 46 | R42: =87+14+54+14+56+13 -> 238 | S42: =SUM(N42,P42,Q42,R42) -> 409 | V42: 80 | W42: 39 | X42: ='WFC LLM API'!F188 -> 0.85 | Y42: =SUM(U42:W42) -> 119 | AB42: =666/250*60+30 -> 189.84 | AC42: 21 | AD42: =SUM(AA42:AC42) -> 210.84 | AF42: 45382 | AG42: =L42-Y42 -> 17 | AH42: =L42-AD42 -> -74.84 | AT42: 45382 | AU42: =L42 -> 136 | AV42: =AD42 -> 210.84 | AX42: =AV42-AU42 -> 74.84 | AY42: =(-AX42/AU42) -> -0.55029412 | BH42: 45382 | BI42: =AU42 -> 136 | BJ42: =Y42 -> 119 | BL42: =BJ42-BI42 -> -17 | BM42: =(-BL42/BI42) -> 0.125 | BU42: =B42 -> WFC | BV42: 45382 | BW42: =L42-AD42 -> -74.84 | BZ42: =L42-Y42 -> 17
G43: =SUM(G39:G42) -> 1000 | K43: Cumulative Total | L43: =SUM(L39:L42) -> 544 | S43: =SUM(S39:S42) -> 1646 | W43: Cumulative Total | Y43: =SUM(Y39:Y42) -> 445.66667 | AC43: Cumulative Total | AD43: =SUM(AD39:AD42) -> 882.36 | AF43: Total | AG43: =SUM(AG39:AG42) -> 98.333333 | AH43: =SUM(AH39:AH42) -> -338.36 | BV43: Quarter Breakeven | BW43: =AA40/AVERAGE(BW39:BX42) -> -11.405603 | BZ43: =U40/AVERAGE(BZ39:CA42) -> 28.516881
R44: Cumulative Efficiency % | S44: =(($L43-S43)/$L43)*1 -> -2.0257353 | W44: Cumulative Efficiency % | Y44: =(($L43-Y43)/$L43)*1 -> 0.1807598 | AC44: Cumulative Efficiency % | AD44: =(($L43-AD43)/$L43)*1 -> -0.62198529
W45: Average Accuracy | X45: =AVERAGE(X39:X42) -> 0.83333333
AB46: =AVERAGE(AB41:AB42,AB39) -> 192.84 | AC46: =AVERAGE(AC39:AC42) -> 27.75
D51: Excel (Manual - Presentation / 10-Q) | I51: Advanced Excel Manual Benchmark (10-Q) | N51: LLM (10-Q) | U51: LLM API (Presentation) | AA51: Python Modules (10-Q)
...

Sheet Application

Sheet Single Generic Prompt
B2: Prompt (v1)
B29: CMA 4Q24 | D29: CRE Total: | E29: 9.4 | Q29: LLM Generic Prompt Application Feature (4Q24 Presentation) | W29: Time Delta | X29: Accuracy Delta | Z29: LLM Ticker Specific Prompt (4Q24 Presentation) | AF29: Time Delta | AG29: Accuracy Delta | AI29: Python Script (4Q24 Presentation) | AO29: Time Delta | AP29: Accuracy Delta | AR29: Manual (4Q24 Presentation)
Q30: (time measured in seconds) | Z30: (time measured in seconds) | AI30: (time measured in seconds) | AR30: (time measured in seconds)
D31: Correct | Q31: Ticker | R31: Execution | S31: Override | T31: Total | U31: Accuracy | Z31: Ticker | AA31: Execution | AB31: Override | AC31: Total | AD31: Accuracy | AI31: Ticker | AJ31: Execution | AK31: Adjustment | AL31: Total | AM31: Accuracy | AR31: Ticker | AS31: Execution | AT31: Adjustment | AU31: Total | AV31: Accuracy
Q32: BAC | R32: 30 | S32: 32 | T32: =SUM(R32:S32) -> 62 | U32: =H232 -> 0.55555556 | W32: =T32-AC32 -> 6 | X32: =U32-AD32 -> -0.14444444 | Z32: BAC | AA32: =Summary!W26 -> 19 | AB32: =Summary!V26 -> 37 | AC32: =SUM(AA32:AB32) -> 56 | AD32: =Summary!X26 -> 0.7 | AF32: =T32-AL32 -> -28 | AG32: =U32-AM32 -> -0.44444444 | AI32: BAC | AJ32: =Summary!AC26 -> 28 | AK32: =Summary!AB26 -> 62 | AL32: =SUM(AJ32:AK32) -> 90 | AM32: 1 | AO32: =T32-AU32 -> -14 | AP32: =U32-AV32 -> -0.44444444 | AR32: BAC | AS32: =Summary!I26 -> 30 | AT32: =SUM(Summary!J26:K26) -> 46 | AU32: =SUM(AS32:AT32) -> 76 | AV32: 1
D33: CRE Property Types | E33: Percentage | F33: Loan Amount ($bn) | G33: Loan Amount ($mn) | Q33: FCNCA | R33: 24 | S33: 13 | T33: =SUM(R33:S33) -> 37 | U33: =H261 -> 0.92857143 | W33: =T33-AC33 -> 9 | X33: =U33-AD33 -> -0.071428571 | Z33: FCNCA | AA33: =Summary!W139 -> 26 | AB33: =Summary!V139 -> 2 | AC33: =SUM(AA33:AB33) -> 28 | AD33: =Summary!X139 -> 1 | AF33: =T33-AL33 -> -3 | AG33: =U33-AM33 -> -0.071428571 | AI33: FCNCA | AJ33: =Summary!AC139 -> 16 | AK33: =Summary!AB139 -> 24 | AL33: =SUM(AJ33:AK33) -> 40 | AM33: 1 | AO33: =T33-AU33 -> -51 | AP33: =U33-AV33 -> -0.071428571 | AR33: FCNCA | AS33: =Summary!I139 -> 27 | AT33: =SUM(Summary!J139:K139) -> 61 | AU33: =SUM(AS33:AT33) -> 88 | AV33: 1
D34: Industrial | E34: 0.29 | F34: =$E$29*E34 -> 2.726 | G34: =F34*1000 -> 2726 | Q34: CFG | R34: 21 | S34: 19 | T34: =SUM(R34:S34) -> 40 | U34: =H289 -> 0.85714286 | W34: =T34-AC34 -> 15 | X34: =U34-AD34 -> -0.14285714 | Z34: CFG | AA34: =Summary!W123 -> 23 | AB34: =Summary!V123 -> 2 | AC34: =SUM(AA34:AB34) -> 25 | AD34: =Summary!X123 -> 1 | AF34: =T34-AL34 -> 0 | AG34: =U34-AM34 -> -0.14285714 | AI34: CFG | AJ34: =Summary!AC123 -> 18 | AK34: =Summary!AB123 -> 22 | AL34: =SUM(AJ34:AK34) -> 40 | AM34: 1 | AO34: =T34-AU34 -> -66 | AP34: =U34-AV34 -> -0.14285714 | AR34: CFG | AS34: =Summary!I123 -> 32 | AT34: =SUM(Summary!J123:K123) -> 74 | AU34: =SUM(AS34:AT34) -> 106 | AV34: 1
D35: Multi-family | E35: 0.48 | F35: =$E$29*E35 -> 4.512 | G35: =F35*1000 -> 4512 | Q35: HBAN | R35: 21 | S35: 0 | T35: =SUM(R35:S35) -> 21 | U35: =H316 -> 1 | W35: =T35-AC35 -> -3 | X35: =U35-AD35 -> 0 | Z35: HBAN | AA35: =Summary!W105 -> 22 | AB35: =Summary!V105 -> 2 | AC35: =SUM(AA35:AB35) -> 24 | AD35: =Summary!X105 -> 1 | AF35: =T35-AL35 -> -139 | AG35: =U35-AM35 -> 0 | AI35: HBAN | AJ35: =Summary!AC105 -> 15 | AK35: =Summary!AB105 -> 145 | AL35: =SUM(AJ35:AK35) -> 160 | AM35: 1 | AO35: =T35-AU35 -> -35 | AP35: =U35-AV35 -> 0 | AR35: HBAN | AS35: =Summary!I105 -> 24 | AT35: =SUM(Summary!J105:K105) -> 32 | AU35: =SUM(AS35:AT35) -> 56 | AV35: 1
D36: Self-Storage | E36: 0.05 | F36: =$E$29*E36 -> 0.47 | G36: =F36*1000 -> 470 | Q36: RF | R36: 21 | S36: 20 | T36: =SUM(R36:S36) -> 41 | U36: =H364 -> 0.8125 | W36: =T36-AC36 -> -25 | X36: =U36-AD36 -> -0.1875 | Z36: RF | AA36: =Summary!W180 -> 31 | AB36: =Summary!V180 -> 35 | AC36: =SUM(AA36:AB36) -> 66 | AD36: =Summary!X180 -> 1 | AF36: =T36-AL36 -> -131.68 | AG36: =U36-AM36 -> -0.1875 | AI36: RF | AJ36: =Summary!AC180 -> 20 | AK36: =Summary!AB180 -> 152.68 | AL36: =SUM(AJ36:AK36) -> 172.68 | AM36: 1 | AO36: =T36-AU36 -> -80 | AP36: =U36-AV36 -> -0.1875 | AR36: RF | AS36: =Summary!I180 -> 24 | AT36: =SUM(Summary!J180:K180) -> 97 | AU36: =SUM(AS36:AT36) -> 121 | AV36: 1
D37: Retail | E37: 0.04 | F37: =$E$29*E37 -> 0.376 | G37: =F37*1000 -> 376 | Q37: PNC | R37: 27 | S37: 0 | T37: =SUM(R37:S37) -> 27 | U37: =H393 -> 1 | W37: =T37-AC37 -> -26 | X37: =U37-AD37 -> 0.071428571 | Z37: PNC | AA37: =Summary!W71 -> 26 | AB37: =Summary!V71 -> 27 | AC37: =SUM(AA37:AB37) -> 53 | AD37: =Summary!X71 -> 0.92857143 | AF37: =T37-AL37 -> -18 | AG37: =U37-AM37 -> 0 | AI37: PNC | AJ37: =Summary!AC71 -> 15 | AK37: =Summary!AB71 -> 30 | AL37: =SUM(AJ37:AK37) -> 45 | AM37: 1 | AO37: =T37-AU37 -> -38 | AP37: =U37-AV37 -> 0 | AR37: PNC | AS37: =Summary!I71 -> 22 | AT37: =SUM(Summary!J71:K71) -> 43 | AU37: =SUM(AS37:AT37) -> 65 | AV37: 1
D38: Office | E38: 0.04 | F38: =$E$29*E38 -> 0.376 | G38: =F38*1000 -> 376 | Q38: SNV | R38: 23 | S38: 18 | T38: =SUM(R38:S38) -> 41 | U38: =H420 -> 0.9375 | W38: =T38-AC38 -> 15 | X38: =U38-AD38 -> -0.0625 | Z38: SNV | AA38: =Summary!W159 -> 24 | AB38: =Summary!V159 -> 2 | AC38: =SUM(AA38:AB38) -> 26 | AD38: =Summary!X159 -> 1 | AF38: =T38-AL38 -> -115 | AG38: =U38-AM38 -> -0.0625 | AI38: SNV | AJ38: =Summary!AC159 -> 30 | AK38: =Summary!AB159 -> 126 | AL38: =SUM(AJ38:AK38) -> 156 | AM38: 1 | AO38: =T38-AU38 -> -77 | AP38: =U38-AV38 -> -0.0625 | AR38: SNV | AS38: =Summary!I159 -> 47 | AT38: =SUM(Summary!J159:K159) -> 71 | AU38: =SUM(AS38:AT38) -> 118 | AV38: 1
D39: Single Family / Land Development | E39: 0.03 | F39: =$E$29*E39 -> 0.282 | G39: =F39*1000 -> 282 | Q39: KEY | R39: 22 | S39: 14 | T39: =SUM(R39:S39) -> 36 | U39: =H467 -> 0.85714286 | W39: =T39-AC39 -> -23 | X39: =U39-AD39 -> -0.14285714 | Z39: KEY | AA39: =Summary!W87 -> 28 | AB39: =Summary!V87 -> 31 | AC39: =SUM(AA39:AB39) -> 59 | AD39: =Summary!X87 -> 1 | AF39: =T39-AL39 -> -24 | AG39: =U39-AM39 -> -0.14285714 | AI39: KEY | AJ39: =Summary!AC87 -> 12 | AK39: =Summary!AB87 -> 48 | AL39: =SUM(AJ39:AK39) -> 60 | AM39: 1 | AO39: =T39-AU39 -> -113 | AP39: =U39-AV39 -> -0.14285714 | AR39: KEY | AS39: =Summary!I87 -> 47 | AT39: =SUM(Summary!J87:K87) -> 102 | AU39: =SUM(AS39:AT39) -> 149 | AV39: 1
D40: Land Carry | E40: 0.03 | F40: =$E$29*E40 -> 0.282 | G40: =F40*1000 -> 282 | Q40: WFC | R40: 24 | S40: 29 | T40: =SUM(R40:S40) -> 53 | U40: =H509 -> 0.75 | W40: =T40-AC40 -> -56 | X40: =U40-AD40 -> -0.083333333 | Z40: WFC | AA40: =Summary!W39 -> 24 | AB40: =Summary!V39 -> 85 | AC40: =SUM(AA40:AB40) -> 109 | AD40: =Summary!X39 -> 0.83333333 | AF40: =T40-AL40 -> -171.84 | AG40: =U40-AM40 -> -0.25 | AI40: WFC | AJ40: =Summary!AC39 -> 25 | AK40: =Summary!AB39 -> 199.84 | AL40: =SUM(AJ40:AK40) -> 224.84 | AM40: 1 | AO40: =T40-AU40 -> -83 | AP40: =U40-AV40 -> -0.25 | AR40: WFC | AS40: =Summary!I39 -> 52 | AT40: =SUM(Summary!J39:K39) -> 84 | AU40: =SUM(AS40:AT40) -> 136 | AV40: 1
D41: Multi-use | E41: 0.02 | F41: =$E$29*E41 -> 0.188 | G41: =F41*1000 -> 188 | Q41: JPM | R41: 25 | S41: 15 | T41: =SUM(R41:S41) -> 40 | U41: =H549 -> 0.78571429 | W41: =T41-AC41 -> -59 | X41: =U41-AD41 -> -0.026785714 | Z41: JPM | AA41: =Summary!W54 -> 34 | AB41: =Summary!V54 -> 65 | AC41: =SUM(AA41:AB41) -> 99 | AD41: =Summary!X54 -> 0.8125 | AF41: =T41-AL41 -> 2 | AG41: =U41-AM41 -> -0.21428571 | AI41: JPM | AJ41: =Summary!AC54 -> 18 | AK41: =Summary!AB54 -> 20 | AL41: =SUM(AJ41:AK41) -> 38 | AM41: 1 | AO41: =T41-AU41 -> -83 | AP41: =U41-AV41 -> -0.21428571 | AR41: JPM | AS41: =Summary!I54 -> 49 | AT41: =SUM(Summary!J54:K54) -> 74 | AU41: =SUM(AS41:AT41) -> 123 | AV41: 1
D42: Other | E42: 0.02 | F42: =$E$29*E42 -> 0.188 | G42: =F42*1000 -> 188 | Q42: Total | R42: =SUM(R32:R41) -> 238 | S42: =SUM(S32:S41) -> 160 | T42: =SUM(T32:T41) -> 398 | U42: =AVERAGE(U32:U41) -> 0.8484127 | W42: =T42-AC42 -> -147 | X42: =U42-AD42 -> -0.079027778 | Z42: Total | AA42: =SUM(AA32:AA41) -> 257 | AB42: =SUM(AB32:AB41) -> 288 | AC42: =SUM(AC32:AC41) -> 545 | AD42: =AVERAGE(AD32:AD41) -> 0.92744048 | AF42: =T42-AL42 -> -628.52 | AG42: =U42-AM42 -> -0.1515873 | AI42: Total | AJ42: =SUM(AJ32:AJ41) -> 197 | AK42: =SUM(AK32:AK41) -> 829.52 | AL42: =SUM(AL32:AL41) -> 1026.52 | AM42: =AVERAGE(AM32:AM41) -> 1 | AO42: =T42-AU42 -> -640 | AP42: =U42-AV42 -> -0.1515873 | AR42: Total | AS42: =SUM(AS32:AS41) -> 354 | AT42: =SUM(AT32:AT41) -> 684 | AU42: =SUM(AU32:AU41) -> 1038 | AV42: =AVERAGE(AV32:AV41) -> 1
E43: =SUM(E34:E42) -> 1 | F43: =SUM(F34:F42) -> 9.4 | G43: =SUM(G34:G42) -> 9400 | T43: =T42/AC42-1 -> -0.26972477
Q44: CMA | R44: 35 | S44: 0 | T44: =SUM(R44:S44) -> 35 | U44: =H57 -> 1
D45: Standardized | G45: LLM | Q45: VLY | R45: 22 | S45: 20 | T45: =SUM(R45:S45) -> 42 | U45: =H100 -> 0.92857143
Q46: TD | R46: 21 | S46: 0 | T46: =SUM(R46:S46) -> 21 | U46: =H127 -> 1
D47: Property Type | E47: Amount | G47: Property Type | H47: Amount | Q47: CIBC | R47: 23 | S47: 22 | T47: =SUM(R47:S47) -> 45 | U47: =H197 -> 0.9375
D48: Industrial | E48: =G34 -> 2726 | G48: Industrial | H48: 2726 | J48: =D48=G48 -> TRUE | K48: =E48=H48 -> TRUE | Q48: BKU | R48: 28 | S48: 0 | T48: =SUM(R48:S48) -> 28 | U48: =H154 -> 1
D49: Multi-family | E49: =G35 -> 4512 | G49: Multi-family | H49: 4512 | J49: =D49=G49 -> TRUE | K49: =E49=H49 -> TRUE | Q49: Total | R49: =SUM(R44:R48) -> 129 | S49: =SUM(S44:S48) -> 42 | T49: =SUM(T44:T48) -> 171 | U49: =AVERAGE(U44:U48) -> 0.97321429
D50: Retail | E50: =G37 -> 376 | G50: Retail | H50: 376 | J50: =D50=G50 -> TRUE | K50: =E50=H50 -> TRUE
D51: Office | E51: =G38 -> 376 | G51: Office | H51: 376 | J51: =D51=G51 -> TRUE | K51: =E51=H51 -> TRUE
D52: Residential | E52: =G39 -> 282 | G52: Residential | H52: 282 | J52: =D52=G52 -> TRUE | K52: =E52=H52 -> TRUE
D53: Mixed-use | E53: =G41 -> 188 | G53: Mixed-use | H53: 188 | J53: =D53=G53 -> TRUE | K53: =E53=H53 -> TRUE
D54: Other | E54: =G42+G36+G40 -> 940 | G54: Other | H54: 941 | J54: =D54=G54 -> TRUE | K54: TRUE
D55: Total CRE | E55: =SUM(E48:E54) -> 9400 | G55: Total CRE | H55: =SUM(H48:H54) -> 9401 | J55: =D55=G55 -> TRUE | K55: TRUE
G57: Accuracy | H57: =16/16 -> 1
B74: VLY 4Q24 | D74: CRE Total: | E74: 26.5
D76: Correct
D78: CRE Property Types | E78: Percentage | F78: Loan Amount ($bn) | G78: Loan Amount ($mn)
D79: Retail | E79: 0.17 | F79: =$E$74*E79 -> 4.505 | G79: =F79*1000 -> 4505
D80: Mixed-Use | E80: 0.1 | F80: =$E$74*E80 -> 2.65 | G80: =F80*1000 -> 2650
D81: Office | E81: 0.1 | F81: =$E$74*E81 -> 2.65 | G81: =F81*1000 -> 2650
D82: Healthcare Office | E82: 0.02 | F82: =$E$74*E82 -> 0.53 | G82: =F82*1000 -> 530
D83: Industrial | E83: 0.11 | F83: =$E$74*E83 -> 2.915 | G83: =F83*1000 -> 2915
D84: Healthcare | E84: 0.09 | F84: =$E$74*E84 -> 2.385 | G84: =F84*1000 -> 2385
D85: Specialty & Other | E85: 0.11 | F85: =$E$74*E85 -> 2.915 | G85: =F85*1000 -> 2915
D86: Apartment & Residential | E86: 0.3 | F86: =$E$74*E86 -> 7.95 | G86: =F86*1000 -> 7950
...

Sheet Two Generic Prompts
D2: Value Table Prompt | L2: Pie Chart Prompt
B3: Prompt (v2)
B29: CMA 4Q24 | D29: CRE Total: | E29: 9.4 | Q29: LLM Generic Prompt Application Feature (4Q24 Presentation) | W29: Time Delta vs V1 | X29: Accuracy Delta | Y29: Time Delta | Z29: Accuracy Delta | AB29: LLM Ticker Specific Prompt (4Q24 Presentation) | AH29: Time Delta | AI29: Accuracy Delta | AK29: Python Script (4Q24 Presentation) | AQ29: Time Delta | AR29: Accuracy Delta | AT29: Manual (4Q24 Presentation)
Q30: (time measured in seconds) | AB30: (time measured in seconds) | AK30: (time measured in seconds) | AT30: (time measured in seconds)
D31: Correct | Q31: Ticker | R31: Execution | S31: Override | T31: Total | U31: Accuracy | AB31: Ticker | AC31: Execution | AD31: Override | AE31: Total | AF31: Accuracy | AK31: Ticker | AL31: Execution | AM31: Adjustment | AN31: Total | AO31: Accuracy | AT31: Ticker | AU31: Execution | AV31: Adjustment | AW31: Total | AX31: Accuracy
Q32: BAC | R32: 35 | S32: 33 | T32: =SUM(R32:S32) -> 68 | U32: =H232 -> 0.55555556 | W32: =T32-'Single Generic Prompt'!T32 -> 6 | X32: =U32-'Single Generic Prompt'!U32 -> 0 | Y32: =T32-AE32 -> 12 | Z32: =U32-AF32 -> -0.14444444 | AB32: BAC | AC32: =Summary!W26 -> 19 | AD32: =Summary!V26 -> 37 | AE32: =SUM(AC32:AD32) -> 56 | AF32: =Summary!X26 -> 0.7 | AH32: =T32-AN32 -> -22 | AI32: =U32-AO32 -> -0.44444444 | AK32: BAC | AL32: =Summary!AC26 -> 28 | AM32: =Summary!AB26 -> 62 | AN32: =SUM(AL32:AM32) -> 90 | AO32: 1 | AQ32: =T32-AW32 -> -8 | AR32: =U32-AX32 -> -0.44444444 | AT32: BAC | AU32: =Summary!I26 -> 30 | AV32: =SUM(Summary!J26:K26) -> 46 | AW32: =SUM(AU32:AV32) -> 76 | AX32: 1
D33: CRE Property Types | E33: Percentage | F33: Loan Amount ($bn) | G33: Loan Amount ($mn) | Q33: FCNCA | R33: 32 | S33: 0 | T33: =SUM(R33:S33) -> 32 | U33: =H261 -> 1 | W33: =T33-'Single Generic Prompt'!T33 -> -5 | X33: =U33-'Single Generic Prompt'!U33 -> 0.071428571 | Y33: =T33-AE33 -> 4 | Z33: =U33-AF33 -> 0 | AB33: FCNCA | AC33: =Summary!W139 -> 26 | AD33: =Summary!V139 -> 2 | AE33: =SUM(AC33:AD33) -> 28 | AF33: =Summary!X139 -> 1 | AH33: =T33-AN33 -> -8 | AI33: =U33-AO33 -> 0 | AK33: FCNCA | AL33: =Summary!AC139 -> 16 | AM33: =Summary!AB139 -> 24 | AN33: =SUM(AL33:AM33) -> 40 | AO33: 1 | AQ33: =T33-AW33 -> -56 | AR33: =U33-AX33 -> 0 | AT33: FCNCA | AU33: =Summary!I139 -> 27 | AV33: =SUM(Summary!J139:K139) -> 61 | AW33: =SUM(AU33:AV33) -> 88 | AX33: 1
D34: Industrial | E34: 0.29 | F34: =$E$29*E34 -> 2.726 | G34: =F34*1000 -> 2726 | Q34: CFG | R34: 29 | S34: 0 | T34: =SUM(R34:S34) -> 29 | U34: =H289 -> 1 | W34: =T34-'Single Generic Prompt'!T34 -> -11 | X34: =U34-'Single Generic Prompt'!U34 -> 0.14285714 | Y34: =T34-AE34 -> 4 | Z34: =U34-AF34 -> 0 | AB34: CFG | AC34: =Summary!W123 -> 23 | AD34: =Summary!V123 -> 2 | AE34: =SUM(AC34:AD34) -> 25 | AF34: =Summary!X123 -> 1 | AH34: =T34-AN34 -> -11 | AI34: =U34-AO34 -> 0 | AK34: CFG | AL34: =Summary!AC123 -> 18 | AM34: =Summary!AB123 -> 22 | AN34: =SUM(AL34:AM34) -> 40 | AO34: 1 | AQ34: =T34-AW34 -> -77 | AR34: =U34-AX34 -> 0 | AT34: CFG | AU34: =Summary!I123 -> 32 | AV34: =SUM(Summary!J123:K123) -> 74 | AW34: =SUM(AU34:AV34) -> 106 | AX34: 1
D35: Multi-family | E35: 0.48 | F35: =$E$29*E35 -> 4.512 | G35: =F35*1000 -> 4512 | Q35: HBAN | R35: 33 | S35: 0 | T35: =SUM(R35:S35) -> 33 | U35: =H316 -> 1 | W35: =T35-'Single Generic Prompt'!T35 -> 12 | X35: =U35-'Single Generic Prompt'!U35 -> 0 | Y35: =T35-AE35 -> 9 | Z35: =U35-AF35 -> 0 | AB35: HBAN | AC35: =Summary!W105 -> 22 | AD35: =Summary!V105 -> 2 | AE35: =SUM(AC35:AD35) -> 24 | AF35: =Summary!X105 -> 1 | AH35: =T35-AN35 -> -127 | AI35: =U35-AO35 -> 0 | AK35: HBAN | AL35: =Summary!AC105 -> 15 | AM35: =Summary!AB105 -> 145 | AN35: =SUM(AL35:AM35) -> 160 | AO35: 1 | AQ35: =T35-AW35 -> -23 | AR35: =U35-AX35 -> 0 | AT35: HBAN | AU35: =Summary!I105 -> 24 | AV35: =SUM(Summary!J105:K105) -> 32 | AW35: =SUM(AU35:AV35) -> 56 | AX35: 1
D36: Self-Storage | E36: 0.05 | F36: =$E$29*E36 -> 0.47 | G36: =F36*1000 -> 470 | Q36: RF | R36: 43 | S36: 6 | T36: =SUM(R36:S36) -> 49 | U36: =H364 -> 0.875 | W36: =T36-'Single Generic Prompt'!T36 -> 8 | X36: =U36-'Single Generic Prompt'!U36 -> 0.0625 | Y36: =T36-AE36 -> -17 | Z36: =U36-AF36 -> -0.125 | AB36: RF | AC36: =Summary!W180 -> 31 | AD36: =Summary!V180 -> 35 | AE36: =SUM(AC36:AD36) -> 66 | AF36: =Summary!X180 -> 1 | AH36: =T36-AN36 -> -123.68 | AI36: =U36-AO36 -> -0.125 | AK36: RF | AL36: =Summary!AC180 -> 20 | AM36: =Summary!AB180 -> 152.68 | AN36: =SUM(AL36:AM36) -> 172.68 | AO36: 1 | AQ36: =T36-AW36 -> -72 | AR36: =U36-AX36 -> -0.125 | AT36: RF | AU36: =Summary!I180 -> 24 | AV36: =SUM(Summary!J180:K180) -> 97 | AW36: =SUM(AU36:AV36) -> 121 | AX36: 1
D37: Retail | E37: 0.04 | F37: =$E$29*E37 -> 0.376 | G37: =F37*1000 -> 376 | Q37: PNC | R37: 28 | S37: 0 | T37: =SUM(R37:S37) -> 28 | U37: =H393 -> 1 | W37: =T37-'Single Generic Prompt'!T37 -> 1 | X37: =U37-'Single Generic Prompt'!U37 -> 0 | Y37: =T37-AE37 -> -25 | Z37: =U37-AF37 -> 0.071428571 | AB37: PNC | AC37: =Summary!W71 -> 26 | AD37: =Summary!V71 -> 27 | AE37: =SUM(AC37:AD37) -> 53 | AF37: =Summary!X71 -> 0.92857143 | AH37: =T37-AN37 -> -17 | AI37: =U37-AO37 -> 0 | AK37: PNC | AL37: =Summary!AC71 -> 15 | AM37: =Summary!AB71 -> 30 | AN37: =SUM(AL37:AM37) -> 45 | AO37: 1 | AQ37: =T37-AW37 -> -37 | AR37: =U37-AX37 -> 0 | AT37: PNC | AU37: =Summary!I71 -> 22 | AV37: =SUM(Summary!J71:K71) -> 43 | AW37: =SUM(AU37:AV37) -> 65 | AX37: 1
D38: Office | E38: 0.04 | F38: =$E$29*E38 -> 0.376 | G38: =F38*1000 -> 376 | Q38: SNV | R38: 32 | S38: 0 | T38: =SUM(R38:S38) -> 32 | U38: =H420 -> 1 | W38: =T38-'Single Generic Prompt'!T38 -> -9 | X38: =U38-'Single Generic Prompt'!U38 -> 0.0625 | Y38: =T38-AE38 -> 6 | Z38: =U38-AF38 -> 0 | AB38: SNV | AC38: =Summary!W159 -> 24 | AD38: =Summary!V159 -> 2 | AE38: =SUM(AC38:AD38) -> 26 | AF38: =Summary!X159 -> 1 | AH38: =T38-AN38 -> -124 | AI38: =U38-AO38 -> 0 | AK38: SNV | AL38: =Summary!AC159 -> 30 | AM38: =Summary!AB159 -> 126 | AN38: =SUM(AL38:AM38) -> 156 | AO38: 1 | AQ38: =T38-AW38 -> -86 | AR38: =U38-AX38 -> 0 | AT38: SNV | AU38: =Summary!I159 -> 47 | AV38: =SUM(Summary!J159:K159) -> 71 | AW38: =SUM(AU38:AV38) -> 118 | AX38: 1
D39: Single Family / Land Development | E39: 0.03 | F39: =$E$29*E39 -> 0.282 | G39: =F39*1000 -> 282 | Q39: KEY | R39: 37 | S39: 0 | T39: =SUM(R39:S39) -> 37 | U39: =H468 -> 1 | W39: =T39-'Single Generic Prompt'!T39 -> 1 | X39: =U39-'Single Generic Prompt'!U39 -> 0.14285714 | Y39: =T39-AE39 -> -22 | Z39: =U39-AF39 -> 0 | AB39: KEY | AC39: =Summary!W87 -> 28 | AD39: =Summary!V87 -> 31 | AE39: =SUM(AC39:AD39) -> 59 | AF39: =Summary!X87 -> 1 | AH39: =T39-AN39 -> -23 | AI39: =U39-AO39 -> 0 | AK39: KEY | AL39: =Summary!AC87 -> 12 | AM39: =Summary!AB87 -> 48 | AN39: =SUM(AL39:AM39) -> 60 | AO39: 1 | AQ39: =T39-AW39 -> -112 | AR39: =U39-AX39 -> 0 | AT39: KEY | AU39: =Summary!I87 -> 47 | AV39: =SUM(Summary!J87:K87) -> 102 | AW39: =SUM(AU39:AV39) -> 149 | AX39: 1
D40: Land Carry | E40: 0.03 | F40: =$E$29*E40 -> 0.282 | G40: =F40*1000 -> 282 | Q40: WFC | R40: 33 | S40: 8 | T40: =SUM(R40:S40) -> 41 | U40: =H510 -> 0.875 | W40: =T40-'Single Generic Prompt'!T40 -> -12 | X40: =U40-'Single Generic Prompt'!U40 -> 0.125 | Y40: =T40-AE40 -> -68 | Z40: =U40-AF40 -> 0.041666667 | AB40: WFC | AC40: =Summary!W39 -> 24 | AD40: =Summary!V39 -> 85 | AE40: =SUM(AC40:AD40) -> 109 | AF40: =Summary!X39 -> 0.83333333 | AH40: =T40-AN40 -> -183.84 | AI40: =U40-AO40 -> -0.125 | AK40: WFC | AL40: =Summary!AC39 -> 25 | AM40: =Summary!AB39 -> 199.84 | AN40: =SUM(AL40:AM40) -> 224.84 | AO40: 1 | AQ40: =T40-AW40 -> -95 | AR40: =U40-AX40 -> -0.125 | AT40: WFC | AU40: =Summary!I39 -> 52 | AV40: =SUM(Summary!J39:K39) -> 84 | AW40: =SUM(AU40:AV40) -> 136 | AX40: 1
D41: Multi-use | E41: 0.02 | F41: =$E$29*E41 -> 0.188 | G41: =F41*1000 -> 188 | Q41: JPM | R41: 30 | S41: 8 | T41: =SUM(R41:S41) -> 38 | U41: =H550 -> 0.85714286 | W41: =T41-'Single Generic Prompt'!T41 -> -2 | X41: =U41-'Single Generic Prompt'!U41 -> 0.071428571 | Y41: =T41-AE41 -> -61 | Z41: =U41-AF41 -> 0.044642857 | AB41: JPM | AC41: =Summary!W54 -> 34 | AD41: =Summary!V54 -> 65 | AE41: =SUM(AC41:AD41) -> 99 | AF41: =Summary!X54 -> 0.8125 | AH41: =T41-AN41 -> 0 | AI41: =U41-AO41 -> -0.14285714 | AK41: JPM | AL41: =Summary!AC54 -> 18 | AM41: =Summary!AB54 -> 20 | AN41: =SUM(AL41:AM41) -> 38 | AO41: 1 | AQ41: =T41-AW41 -> -85 | AR41: =U41-AX41 -> -0.14285714 | AT41: JPM | AU41: =Summary!I54 -> 49 | AV41: =SUM(Summary!J54:K54) -> 74 | AW41: =SUM(AU41:AV41) -> 123 | AX41: 1
D42: Other | E42: 0.02 | F42: =$E$29*E42 -> 0.188 | G42: =F42*1000 -> 188 | Q42: Total | R42: =SUM(R32:R41) -> 332 | S42: =SUM(S32:S41) -> 55 | T42: =SUM(T32:T41) -> 387 | U42: =AVERAGE(U32:U41) -> 0.91626984 | W42: =T42-'Single Generic Prompt'!T42 -> -11 | X42: =U42-'Single Generic Prompt'!U42 -> 0.067857143 | Y42: =T42-AE42 -> -158 | Z42: =U42-AF42 -> -0.011170635 | AB42: Total | AC42: =SUM(AC32:AC41) -> 257 | AD42: =SUM(AD32:AD41) -> 288 | AE42: =SUM(AE32:AE41) -> 545 | AF42: =AVERAGE(AF32:AF41) -> 0.92744048 | AH42: =T42-AN42 -> -639.52 | AI42: =U42-AO42 -> -0.083730159 | AK42: Total | AL42: =SUM(AL32:AL41) -> 197 | AM42: =SUM(AM32:AM41) -> 829.52 | AN42: =SUM(AN32:AN41) -> 1026.52 | AO42: =AVERAGE(AO32:AO41) -> 1 | AQ42: =T42-AW42 -> -651 | AR42: =U42-AX42 -> -0.083730159 | AT42: Total | AU42: =SUM(AU32:AU41) -> 354 | AV42: =SUM(AV32:AV41) -> 684 | AW42: =SUM(AW32:AW41) -> 1038 | AX42: =AVERAGE(AX32:AX41) -> 1
E43: =SUM(E34:E42) -> 1 | F43: =SUM(F34:F42) -> 9.4 | G43: =SUM(G34:G42) -> 9400 | R43: =R42/'Single Generic Prompt'!R42-1 -> 0.39495798 | S43: =S42/'Single Generic Prompt'!S42-1 -> -0.65625 | T43: =T42/'Single Generic Prompt'!T42-1 -> -0.027638191 | U43: =T42/AE42-1 -> -0.28990826
Q44: CMA | R44: 36 | S44: 0 | T44: =SUM(R44:S44) -> 36 | U44: =H57 -> 1 | W44: =T44-'Single Generic Prompt'!T44 -> 1 | X44: =U44-'Single Generic Prompt'!U44 -> 0
D45: Standardized | G45: LLM | Q45: VLY | R45: 36 | S45: 0 | T45: =SUM(R45:S45) -> 36 | U45: =H100 -> 1 | W45: =T45-'Single Generic Prompt'!T45 -> -6 | X45: =U45-'Single Generic Prompt'!U45 -> 0.071428571
Q46: TD | R46: 29 | S46: 0 | T46: =SUM(R46:S46) -> 29 | U46: =H127 -> 1 | W46: =T46-'Single Generic Prompt'!T46 -> 8 | X46: =U46-'Single Generic Prompt'!U46 -> 0
D47: Property Type | E47: Amount | G47: Property Type | H47: Amount | Q47: CIBC | R47: 38 | S47: 0 | T47: =SUM(R47:S47) -> 38 | U47: =H197 -> 1 | W47: =T47-'Single Generic Prompt'!T47 -> -7 | X47: =U47-'Single Generic Prompt'!U47 -> 0.0625
D48: Industrial | E48: =G34 -> 2726 | G48: Industrial | H48: 2726 | J48: =D48=G48 -> TRUE | K48: =E48=H48 -> TRUE | Q48: BKU | R48: 25 | S48: 0 | T48: =SUM(R48:S48) -> 25 | U48: =H154 -> 1 | W48: =T48-'Single Generic Prompt'!T48 -> -3 | X48: =U48-'Single Generic Prompt'!U48 -> 0
D49: Multi-family | E49: =G35 -> 4512 | G49: Multi-family | H49: 4512 | J49: =D49=G49 -> TRUE | K49: =E49=H49 -> TRUE | Q49: Total | R49: =SUM(R44:R48) -> 164 | S49: =SUM(S44:S48) -> 0 | T49: =SUM(T44:T48) -> 164 | U49: =AVERAGE(U44:U48) -> 1 | W49: =T49-'Single Generic Prompt'!T49 -> -7 | X49: =U49-'Single Generic Prompt'!U49 -> 0.026785714
D50: Retail | E50: =G37 -> 376 | G50: Retail | H50: 376 | J50: =D50=G50 -> TRUE | K50: =E50=H50 -> TRUE | R50: =R49/'Single Generic Prompt'!R49-1 -> 0.27131783 | S50: =S49/'Single Generic Prompt'!S49-1 -> -1 | T50: =T49/'Single Generic Prompt'!T49-1 -> -0.040935673
D51: Office | E51: =G38 -> 376 | G51: Office | H51: 376 | J51: =D51=G51 -> TRUE | K51: =E51=H51 -> TRUE
D52: Residential | E52: =G39 -> 282 | G52: Residential | H52: 282 | J52: =D52=G52 -> TRUE | K52: =E52=H52 -> TRUE
D53: Mixed-use | E53: =G41 -> 188 | G53: Mixed-use | H53: 188 | J53: =D53=G53 -> TRUE | K53: =E53=H53 -> TRUE
D54: Other | E54: =G42+G36+G40 -> 940 | G54: Other | H54: 940 | J54: =D54=G54 -> TRUE | K54: =E54=H54 -> TRUE
D55: Total CRE | E55: =SUM(E48:E54) -> 9400 | G55: Total CRE | H55: 9400 | J55: =D55=G55 -> TRUE | K55: =E55=H55 -> TRUE
G57: Accuracy | H57: 1
B74: VLY 4Q24 | D74: CRE Total: | E74: 26.5
D76: Correct
D78: CRE Property Types | E78: Percentage | F78: Loan Amount ($bn) | G78: Loan Amount ($mn)
D79: Retail | E79: 0.17 | F79: =$E$74*E79 -> 4.505 | G79: =F79*1000 -> 4505
D80: Mixed-Use | E80: 0.1 | F80: =$E$74*E80 -> 2.65 | G80: =F80*1000 -> 2650
D81: Office | E81: 0.1 | F81: =$E$74*E81 -> 2.65 | G81: =F81*1000 -> 2650
D82: Healthcare Office | E82: 0.02 | F82: =$E$74*E82 -> 0.53 | G82: =F82*1000 -> 530
D83: Industrial | E83: 0.11 | F83: =$E$74*E83 -> 2.915 | G83: =F83*1000 -> 2915
D84: Healthcare | E84: 0.09 | F84: =$E$74*E84 -> 2.385 | G84: =F84*1000 -> 2385
D85: Specialty & Other | E85: 0.11 | F85: =$E$74*E85 -> 2.915 | G85: =F85*1000 -> 2915
...

Sheet BAC

Sheet BAC Manual
A2: 4Q24 | B2: Manual 4Q24 (10-Q)
B4: CRE Property Type | C4: Amount ($bn) | E4: Ticker | F4: Quarter | G4: CRE Property Type | H4: Amount ($bn) | I4: Unit | J4: Currency | K4: Category
B5: Office | C5: 15061 | E5: BAC | F5: 4Q24 | G5: Office | H5: 15061 | I5: mn | J5: USD | K5: CRE
B6: Industrial / Warehouse | C6: 13166 | E6: BAC | F6: 4Q24 | G6: Industrial | H6: 13166 | I6: mn | J6: USD | K6: CRE
B7: Multi-family rental | C7: 11022 | E7: BAC | F7: 4Q24 | G7: Multi-family | H7: 11022 | I7: mn | J7: USD | K7: CRE
B8: Shopping centers / Retail | C8: 5603 | E8: BAC | F8: 4Q24 | G8: Retail | H8: 5603 | I8: mn | J8: USD | K8: CRE
B9: Hotel / Motels | C9: 4680 | E9: BAC | F9: 4Q24 | G9: Lodging | H9: 4680 | I9: mn | J9: USD | K9: CRE
B10: Multi-use | C10: 2162 | E10: BAC | F10: 4Q24 | G10: Mixed-use | H10: 2162 | I10: mn | J10: USD | K10: CRE
B11: Other | C11: 13179 | E11: BAC | F11: 4Q24 | G11: Other | H11: 13179 | I11: mn | J11: USD | K11: CRE
B12: Residential | C12: 857 | E12: BAC | F12: 4Q24 | G12: Residential | H12: 857 | I12: mn | J12: USD | K12: CRE
B13: Total CRE | C13: =SUM(C5:C12) -> 65730 | E13: BAC | F13: 4Q24 | G13: Total CRE | H13: =SUM(H5:H12) -> 65730 | I13: mn | J13: USD | K13: CRE
A15: 3Q24 | B15: Manual 3Q24 (10-Q)
B17: CRE Property Type | C17: Amount ($bn) | E17: Ticker | F17: Quarter | G17: CRE Property Type | H17: Amount ($bn) | I17: Unit | J17: Currency | K17: Category
B18: Office | C18: 15768 | E18: BAC | F18: 3Q24 | G18: Office | H18: 15768 | I18: mn | J18: USD | K18: CRE
B19: Industrial / Warehouse | C19: 13912 | E19: BAC | F19: 3Q24 | G19: Industrial | H19: 13912 | I19: mn | J19: USD | K19: CRE
B20: Multi-family rental | C20: 11670 | E20: BAC | F20: 3Q24 | G20: Multi-family | H20: 11670 | I20: mn | J20: USD | K20: CRE
B21: Shopping centers / Retail | C21: 5423 | E21: BAC | F21: 3Q24 | G21: Retail | H21: 5423 | I21: mn | J21: USD | K21: CRE
B22: Hotel / Motels | C22: 4717 | E22: BAC | F22: 3Q24 | G22: Lodging | H22: 4717 | I22: mn | J22: USD | K22: CRE
B23: Multi-use | C23: 2073 | E23: BAC | F23: 3Q24 | G23: Mixed-use | H23: 2073 | I23: mn | J23: USD | K23: CRE
B24: Other | C24: 14159 | E24: BAC | F24: 3Q24 | G24: Other | H24: 14159 | I24: mn | J24: USD | K24: CRE
B25: Residential | C25: 698 | E25: BAC | F25: 3Q24 | G25: Residential | H25: 698 | I25: mn | J25: USD | K25: CRE
B26: Total CRE | C26: =SUM(C18:C25) -> 68420 | E26: BAC | F26: 3Q24 | G26: Total CRE | H26: 68420 | I26: mn | J26: USD | K26: CRE
A29: 2Q24 | B29: Manual 2Q24 (10-Q)
B31: CRE Property Type | C31: Amount ($bn) | E31: Ticker | F31: Quarter | G31: CRE Property Type | H31: Amount ($bn) | I31: Unit | J31: Currency | K31: Category
B32: Office | C32: 16314 | E32: BAC | F32: 2Q24 | G32: Office | H32: 16314 | I32: mn | J32: USD | K32: CRE
B33: Industrial / Warehouse | C33: 14675 | E33: BAC | F33: 2Q24 | G33: Industrial | H33: 14675 | I33: mn | J33: USD | K33: CRE
B34: Multi-family rental | C34: 11561 | E34: BAC | F34: 2Q24 | G34: Multi-family | H34: 11561 | I34: mn | J34: USD | K34: CRE
B35: Shopping centers / Retail | C35: 5640 | E35: BAC | F35: 2Q24 | G35: Retail | H35: 5640 | I35: mn | J35: USD | K35: CRE
B36: Hotel / Motels | C36: 5051 | E36: BAC | F36: 2Q24 | G36: Lodging | H36: 5051 | I36: mn | J36: USD | K36: CRE
B37: Multi-use | C37: 2131 | E37: BAC | F37: 2Q24 | G37: Mixed-use | H37: 2131 | I37: mn | J37: USD | K37: CRE
B38: Other | C38: 14080 | E38: BAC | F38: 2Q24 | G38: Other | H38: 14080 | I38: mn | J38: USD | K38: CRE
B39: Residential | C39: 832 | E39: BAC | F39: 2Q24 | G39: Residential | H39: 832 | I39: mn | J39: USD | K39: CRE
B40: Total CRE | C40: =SUM(C32:C39) -> 70284 | E40: BAC | F40: 2Q24 | G40: Total CRE | H40: =SUM(H32:H39) -> 70284 | I40: mn | J40: USD | K40: CRE
A43: 1Q24 | B43: Manual 1Q24 (10-Q)
B45: CRE Property Type | C45: Amount ($bn) | E45: Ticker | F45: Quarter | G45: CRE Property Type | H45: Amount ($bn) | I45: Unit | J45: Currency | K45: Category
B46: Office | C46: 17442 | E46: BAC | F46: 1Q24 | G46: Office | H46: 17442 | I46: mn | J46: USD | K46: CRE
B47: Industrial / Warehouse | C47: 14635 | E47: BAC | F47: 1Q24 | G47: Industrial | H47: 14635 | I47: mn | J47: USD | K47: CRE
B48: Multi-family rental | C48: 11414 | E48: BAC | F48: 1Q24 | G48: Multi-family | H48: 11414 | I48: mn | J48: USD | K48: CRE
B49: Shopping centers / Retail | C49: 5682 | E49: BAC | F49: 1Q24 | G49: Retail | H49: 5682 | I49: mn | J49: USD | K49: CRE
B50: Hotel / Motels | C50: 5434 | E50: BAC | F50: 1Q24 | G50: Lodging | H50: 5434 | I50: mn | J50: USD | K50: CRE
...

Sheet BAC LLM API
B2: 4Q24 AI API Script
B29: Correct | E29: LLM
B31: CRE Property Type | C31: Loan Amount | E31: CRE Property Type | F31: Loan Amount | H31: =B31=E31 -> TRUE | I31: =C31=F31 -> TRUE
B32: Office | C32: 15.1 | E32: Office | F32: 15.1 | H32: =B32=E32 -> TRUE | I32: =C32=F32 -> TRUE
B33: Industrial | C33: 13.2 | E33: Industrial | F33: 5.6 | H33: =B33=E33 -> TRUE | I33: =C33=F33 -> FALSE
B34: Multi-family | C34: 11 | E34: Multi-family | F34: 13.2 | H34: =B34=E34 -> TRUE | I34: =C34=F34 -> FALSE
B35: Retail | C35: 5.6 | E35: Retail | F35: 4.7 | H35: =B35=E35 -> TRUE | I35: =C35=F35 -> FALSE
B36: Lodging | C36: 4.7 | E36: Lodging | F36: 11 | H36: =B36=E36 -> TRUE | I36: =C36=F36 -> FALSE
B37: Mixed-use | C37: 2.2 | E37: Mixed-use | F37: 2.2 | H37: =B37=E37 -> TRUE | I37: =C37=F37 -> TRUE
B38: Residential | C38: 0.9 | E38: Residential | F38: 13.2 | H38: =B38=E38 -> TRUE | I38: =C38=F38 -> FALSE
B39: Other | C39: 13.2 | E39: Other | F39: 0.9 | H39: =B39=E39 -> TRUE | I39: =C39=F39 -> FALSE
B40: Total | C40: 66 | E40: Total | F40: =SUM(F32:F39) -> 65.9 | H40: =B40=E40 -> TRUE | I40: TRUE
E42: Accuracy | F42: =14/20 -> 0.7
B45: 3Q24 AI API Script
B70: Correct | E70: LLM
B72: CRE Property Type | C72: Loan Amount | E72: CRE Property Type | F72: Loan Amount | H72: =B72=E72 -> TRUE | I72: =C72=F72 -> TRUE
B73: Office | C73: 15.8 | E73: Office | F73: 15.8 | H73: =B73=E73 -> TRUE | I73: =C73=F73 -> TRUE
B74: Industrial | C74: 13.9 | E74: Industrial | F74: 13.9 | H74: =B74=E74 -> TRUE | I74: =C74=F74 -> TRUE
B75: Multi-family | C75: 11.7 | E75: Multi-family | F75: 11.7 | H75: =B75=E75 -> TRUE | I75: =C75=F75 -> TRUE
B76: Retail | C76: 5.4 | E76: Retail | F76: 5.4 | H76: =B76=E76 -> TRUE | I76: =C76=F76 -> TRUE
B77: Lodging | C77: 4.7 | E77: Lodging | F77: 4.7 | H77: =B77=E77 -> TRUE | I77: =C77=F77 -> TRUE
B78: Multi-use | C78: 2.1 | E78: Multi-use | F78: 2.1 | H78: =B78=E78 -> TRUE | I78: =C78=F78 -> TRUE
B79: Residential | C79: 0.7 | E79: Residential | F79: 14.2 | H79: =B79=E79 -> TRUE | I79: =C79=F79 -> FALSE
B80: Other | C80: 14.2 | E80: Other | F80: 0.7 | H80: =B80=E80 -> TRUE | I80: =C80=F80 -> FALSE
B81: Total | C81: 68 | E81: Total | F81: =SUM(F73:F80) -> 68.5 | H81: =B81=E81 -> TRUE | I81: TRUE
E83: Accuracy | F83: =18/20 -> 0.9
B86: 2Q24 AI API Script
B107: Correct | E107: LLM
B109: CRE Property Type | C109: Loan Amount | E109: CRE Property Type | F109: Loan Amount
B110: Office | C110: 16.3 | E110: Office | F110: 16.3 | H110: =B110=E110 -> TRUE | I110: =C110=F110 -> TRUE
B111: Industrial | C111: 14.7 | E111: Industrial | F111: 14.7 | H111: =B111=E111 -> TRUE | I111: =C111=F111 -> TRUE
B112: Multi-family | C112: 11.6 | E112: Multi-family | F112: 11.6 | H112: =B112=E112 -> TRUE | I112: =C112=F112 -> TRUE
B113: Retail | C113: 5.6 | E113: Retail | F113: 5.6 | H113: =B113=E113 -> TRUE | I113: =C113=F113 -> TRUE
B114: Lodging | C114: 5.1 | E114: Lodging | F114: 5.1 | H114: =B114=E114 -> TRUE | I114: =C114=F114 -> TRUE
B115: Mixed-use | C115: 2.1 | E115: Mixed-use | F115: 2.1 | H115: =B115=E115 -> TRUE | I115: =C115=F115 -> TRUE
B116: Residential | C116: 0.8 | E116: Residential | F116: 0.8 | H116: =B116=E116 -> TRUE | I116: =C116=F116 -> TRUE
B117: Other | C117: 14.1 | E117: Other | F117: 14.1 | H117: =B117=E117 -> TRUE | I117: =C117=F117 -> TRUE
B118: Total | C118: =SUM(C110:C117) -> 70.3 | E118: Total | F118: =SUM(F110:F117) -> 70.3 | H118: =B118=E118 -> TRUE | I118: =C118=F118 -> TRUE
E120: Accuracy | F120: =30/30 -> 1
B122: 1Q24 AI API Script
...

Sheet BAC Script
B2: Script 4Q24 (10-Q) | L2: Script 3Q24 (10-Q)
B14: Script 1Q24 (10-Q) | L14: Script 2Q24 (10-Q)

Sheet JPM

Sheet JPM Manual
A2: 4Q24 | B2: Manual 4Q24 (10-Q)
B4: CRE Property Type | C4: Credit Exposure | D4: % Drawn | E4: Outstanding | H4: CRE Property Type | I4: Outstanding
B5: Multifamily | C5: 124081 | D5: 0.92 | E5: =D5*C5 -> 114154.52 | H5: Multi-family | I5: =E5 -> 114154.52
B6: Industrial | C6: 19109 | D6: 0.72 | E6: =D6*C6 -> 13758.48 | H6: Industrial | I6: =E6 -> 13758.48
B7: Other Income Producing Properties | C7: 16569 | D7: 0.63 | E7: =D7*C7 -> 10438.47 | H7: Office | I7: =E8 -> 13251.6
B8: Office | C8: 16360 | D8: 0.81 | E8: =D8*C8 -> 13251.6 | H8: Retail | I8: =E10 -> 9189.75
B9: Services and Non Income Producing | C9: 14104 | D9: 0.46 | E9: =D9*C9 -> 6487.84 | H9: Lodging | I9: =E11 -> 2424.22
B10: Retail | C10: 12253 | D10: 0.75 | E10: =D10*C10 -> 9189.75 | H10: Other | I10: =SUM(E9,E7) -> 16926.31
B11: Lodging | C11: 4574 | D11: 0.53 | E11: =D11*C11 -> 2424.22 | H11: Total CRE | I11: =SUM(I5:I10) -> 169704.88
B12: Total CRE | C12: =SUM(C5:C11) -> 207050 | D12: =E12/C12 -> 0.81963236 | E12: =SUM(E5:E11) -> 169704.88
A27: 3Q24 | B27: Manual 3Q24 (10-Q)
B29: CRE Property Type | C29: Credit Exposure | D29: % Drawn | E29: Outstanding | H29: CRE Property Type | I29: Outstanding | L29: Ticker | M29: Quarter | N29: CRE Property Type | O29: Loan Amount | P29: Unit | Q29: Currency | R29: Category
B30: Multi-family | C30: 125410 | D30: 0.91 | E30: =D30*C30 -> 114123.1 | H30: Multi-family | I30: 114123.1 | L30: JPM | M30: 3Q24 | N30: Multi-family | O30: 114123.1 | P30: mn | Q30: USD | R30: CRE
B31: Industrial | C31: 19282 | D31: 0.74 | E31: =D31*C31 -> 14268.68 | H31: Industrial | I31: 14268.68 | L31: JPM | M31: 3Q24 | N31: Industrial | O31: 14268.68 | P31: mn | Q31: USD | R31: CRE
B32: Office | C32: 16926 | D32: 0.81 | E32: =D32*C32 -> 13710.06 | H32: Office | I32: 13710.06 | L32: JPM | M32: 3Q24 | N32: Office | O32: 13710.06 | P32: mn | Q32: USD | R32: CRE
B33: Other Income Producing Properties | C33: 15011 | D33: 0.67 | E33: =D33*C33 -> 10057.37 | H33: Retail | I33: 8860.29 | L33: JPM | M33: 3Q24 | N33: Retail | O33: 8860.29 | P33: mn | Q33: USD | R33: CRE
B34: Services and Non Income Producing | C34: 14557 | D34: 0.51 | E34: =D34*C34 -> 7424.07 | H34: Lodging | I34: 2509.65 | L34: JPM | M34: 3Q24 | N34: Lodging | O34: 2509.65 | P34: mn | Q34: USD | R34: CRE
B35: Retail | C35: 12841 | D35: 0.69 | E35: =D35*C35 -> 8860.29 | H35: Other | I35: =SUM(E33:E34) -> 17481.44 | L35: JPM | M35: 3Q24 | N35: Other | O35: 17481.44 | P35: mn | Q35: USD | R35: CRE
B36: Lodging | C36: 4563 | D36: 0.55 | E36: =D36*C36 -> 2509.65 | H36: Total CRE | I36: =SUM(I30:I35) -> 170953.22 | L36: JPM | M36: 3Q24 | N36: Total CRE | O36: =SUM(O30:O35) -> 170953.22 | P36: mn | Q36: USD | R36: CRE
B37: Total CRE | C37: =SUM(C30:C36) -> 208590 | D37: =E37/C37 -> 0.81956575 | E37: =SUM(E30:E36) -> 170953.22
A54: 2Q24 | B54: Manual 2Q24 (10-Q)
B56: CRE Property Type | C56: Credit Exposure | D56: % Drawn | E56: Outstanding | H56: CRE Property Type | I56: Outstanding
B57: Multifamily | C57: 122991 | D57: 0.91 | E57: =D57*C57 -> 111921.81 | H57: Multi-family | I57: =E57 -> 111921.81
B58: Industrial | C58: 20871 | D58: 0.7 | E58: =D58*C58 -> 14609.7 | H58: Industrial | I58: =E58 -> 14609.7
B59: Office | C59: 16460 | D59: 0.84 | E59: =D59*C59 -> 13826.4 | H59: Office | I59: =E59 -> 13826.4
B60: Other Income Producing Properties | C60: 14813 | D60: 0.64 | E60: =D60*C60 -> 9480.32 | H60: Retail | I60: =E62 -> 8877.78
B61: Services and Non Income Producing | C61: 14613 | D61: 0.51 | E61: =D61*C61 -> 7452.63 | H61: Lodging | I61: =E63 -> 2380.86
B62: Retail | C62: 11997 | D62: 0.74 | E62: =D62*C62 -> 8877.78 | H62: Other | I62: =SUM(E60:E61) -> 16932.95
B63: Lodging | C63: 4409 | D63: 0.54 | E63: =D63*C63 -> 2380.86 | H63: Total CRE | I63: =SUM(I57:I62) -> 168549.5
B64: Total CRE | C64: =SUM(C57:C63) -> 206154 | D64: =E64/C64 -> 0.81759025 | E64: =SUM(E57:E63) -> 168549.5
A80: 1Q24 | B80: Manual 1Q24 (10-Q)
B82: CRE Property Type | C82: Credit Exposure | D82: % Drawn | E82: Outstanding | H82: CRE Property Type | I82: Outstanding
B83: Multifamily | C83: 122811 | D83: 0.9 | E83: =D83*C83 -> 110529.9 | H83: Multi-family | I83: =E83 -> 110529.9
B84: Industrial | C84: 20058 | D84: 0.71 | E84: =D84*C84 -> 14241.18 | H84: Industrial | I84: =E84 -> 14241.18
B85: Office | C85: 16300 | D85: 0.82 | E85: =D85*C85 -> 13366 | H85: Office | I85: =E85 -> 13366
B86: Services and Non Income Producing | C86: 15106 | D86: 0.51 | E86: =D86*C86 -> 7704.06 | H86: Retail | I86: =E88 -> 9057.6
B87: Other Income Producing Properties | C87: 14793 | D87: 0.65 | E87: =D87*C87 -> 9615.45 | H87: Lodging | I87: =E89 -> 2405.7
B88: Retail | C88: 12240 | D88: 0.74 | E88: =D88*C88 -> 9057.6 | H88: Other | I88: =SUM(E86:E87) -> 17319.51
B89: Lodging | C89: 4455 | D89: 0.54 | E89: =D89*C89 -> 2405.7 | H89: Total CRE | I89: =SUM(I83:I88) -> 166919.89
B90: Total CRE | C90: =SUM(C83:C89) -> 205763 | D90: =E90/C90 -> 0.81122403 | E90: =SUM(E83:E89) -> 166919.89

Sheet JPM LLM API
B2: 4Q24 AI API Script
B15: Correct
B17: CRE Property Type | C17: Credit Exposure | D17: Percentage Drawn
B18: Multi-family | C18: 124081 | D18: 0.92
B19: Industrial | C19: 19109 | D19: 0.72
B20: Office | C20: 16360 | D20: 0.81
B21: Other Income Producing Properties | C21: 16569 | D21: 0.63
B22: Services and Non Income Producing | C22: 14104 | D22: 0.46
B23: Retail | C23: 12253 | D23: 0.75
B24: Lodging | C24: 4574 | D24: 0.53
B25: Total CRE | C25: =SUM(C18:C24) -> 207050 | D25: 0.82
B37: Correct | E37: LLM
B39: CRE Property Type | C39: Loan Amount | E39: CRE Property Type | F39: Loan Amount | H39: =B39=E39 -> TRUE | I39: =C39=F39 -> TRUE
B40: Multi-family | C40: =C18*D18 -> 114154.52 | E40: Multi-family | F40: 114156 | H40: =B40=E40 -> TRUE | I40: TRUE
B41: Industrial | C41: =C19*D19 -> 13758.48 | E41: Industrial | F41: 13758.48 | H41: =B41=E41 -> TRUE | I41: =C41=F41 -> TRUE
B42: Office | C42: =C20*D20 -> 13251.6 | E42: Office | F42: 13256 | H42: =B42=E42 -> TRUE | I42: =C42=F42 -> FALSE
B43: Other | C43: =C21*D21+C22*D22 -> 16926.31 | E43: Other | F43: 14722 | H43: =B43=E43 -> TRUE | I43: =C43=F43 -> FALSE
B44: Retail | C44: =C23*D23 -> 9189.75 | E44: Retail | F44: 9189.75 | H44: =B44=E44 -> TRUE | I44: =C44=F44 -> TRUE
B45: Lodging | C45: =C24*D24 -> 2424.22 | E45: Lodging | F45: 2424.22 | H45: =B45=E45 -> TRUE | I45: =C45=F45 -> TRUE
B46: Total CRE | C46: =SUM(C40:C45) -> 169704.88 | E46: Total CRE | F46: 167506 | H46: =B46=E46 -> TRUE | I46: =C46=F46 -> FALSE
E48: Accuracy | F48: =13/16 -> 0.8125
B49: Override Table
B60: 3Q24 AI API Script
B74: Correct
B76: CRE Property Type | C76: Credit Exposure | D76: Percentage Drawn
B77: Multi-family | C77: 125410 | D77: 0.91
B78: Industrial | C78: 19282 | D78: 0.74
B79: Office | C79: 16926 | D79: 0.81
B80: Other Income Producing Properties | C80: 15011 | D80: 0.67
B81: Services and Non Income Producing | C81: 14557 | D81: 0.51
B82: Retail | C82: 12841 | D82: 0.69
B83: Lodging | C83: 4563 | D83: 0.55
B84: Total CRE | C84: =SUM(C77:C83) -> 208590 | D84: 0.82
B96: Correct | E96: LLM
B98: CRE Property Type | C98: Loan Amount | E98: CRE Property Type | F98: Loan Amount | H98: =B98=E98 -> TRUE | I98: =C98=F98 -> TRUE
B99: Multi-family | C99: =C77*D77 -> 114123.1 | E99: Multi-family | F99: 114122 | H99: =B99=E99 -> TRUE | I99: TRUE
B100: Industrial | C100: =C78*D78 -> 14268.68 | E100: Industrial | F100: 14272 | H100: =B100=E100 -> TRUE | I100: =C100=F100 -> FALSE
B101: Office | C101: =C79*D79 -> 13710.06 | E101: Office | F101: 13712 | H101: =B101=E101 -> TRUE | I101: =C101=F101 -> FALSE
B102: Other | C102: =C80*D80+C81*D81 -> 17481.44 | E102: Other | F102: 19621 | H102: =B102=E102 -> TRUE | I102: =C102=F102 -> FALSE
B103: Retail | C103: =C82*D82 -> 8860.29 | E103: Retail | F103: 8859 | H103: =B103=E103 -> TRUE | I103: TRUE
...

Sheet JPM Script
B2: Script 4Q24 (10-Q) | K2: Script 3Q24 (10-Q)
B13: Script 2Q24 (10-Q) | K13: Script 1Q24 (10-Q)

Sheet WFC

Sheet WFC Manual
A2: 4Q24 | B2: CRE Property Type | C2: CRE Mortgage | D2: CRE Construction | E2: Total | G2: Ticker | H2: Quarter | I2: CRE Property Type | J2: Loan Amount | K2: Unit | L2: Currency | M2: Category
B3: Apartments | C3: 28359 | D3: 11399 | E3: =SUM(C3:D3) -> 39758 | G3: WFC | H3: 4Q24 | I3: Multi-family | J3: =E3 -> 39758 | K3: mn | L3: USD | M3: CRE
B4: Office | C4: 24818 | D4: 2562 | E4: =SUM(C4:D4) -> 27380 | G4: WFC | H4: 4Q24 | I4: Office | J4: =E4 -> 27380 | K4: mn | L4: USD | M4: CRE
B5: Industrial/warehouse | C5: 20987 | D5: 3051 | E5: =SUM(C5:D5) -> 24038 | G5: WFC | H5: 4Q24 | I5: Industrial | J5: =E5 -> 24038 | K5: mn | L5: USD | M5: CRE
B6: Hotel/motel | C6: 10853 | D6: 653 | E6: =SUM(C6:D6) -> 11506 | G6: WFC | H6: 4Q24 | I6: Retail | J6: =E7+E8 -> 19458 | K6: mn | L6: USD | M6: CRE
B7: Retail (excl shoppingcenter) | C7: 11260 | D7: 85 | E7: =SUM(C7:D7) -> 11345 | G7: WFC | H7: 4Q24 | I7: Lodging | J7: =E6 -> 11506 | K7: mn | L7: USD | M7: CRE
B8: Shopping center | C8: 7860 | D8: 253 | E8: =SUM(C8:D8) -> 8113 | G8: WFC | H8: 4Q24 | I8: Mixed-use | J8: =E10 -> 2316 | K8: mn | L8: USD | M8: CRE
B9: Institutional | C9: 4048 | D9: 1138 | E9: =SUM(C9:D9) -> 5186 | G9: WFC | H9: 4Q24 | I9: Other | J9: =SUM(E11:E12,E9,E13) -> 12049 | K9: mn | L9: USD | M9: CRE
B10: Mixed use properties | C10: 2303 | D10: 13 | E10: =SUM(C10:D10) -> 2316 | G10: WFC | H10: 4Q24 | I10: Total CRE | J10: =SUM(J3:J9) -> 136505 | K10: mn | L10: USD | M10: CRE
B11: Mobile home park | C11: 2273 | D11: — | E11: =SUM(C11:D11) -> 2273
B12: Storage facility | C12: 2040 | D12: 48 | E12: =SUM(C12:D12) -> 2088
B13: Other | C13: 1058 | D13: 1444 | E13: =SUM(C13:D13) -> 2502
B14: Total CRE | C14: =SUM(C3:C13) -> 115859 | D14: =SUM(D3:D13) -> 20646 | E14: =SUM(E3:E13) -> 136505
A16: 3Q24 | B16: CRE Property Type | C16: CRE Mortgage | D16: CRE Construction | E16: Total | G16: Ticker | H16: Quarter | I16: CRE Property Type | J16: Loan Amount | K16: Unit | L16: Currency | M16: Category
B17: Apartments | C17: 29374 | D17: 11975 | E17: =SUM(C17:D17) -> 41349 | G17: WFC | H17: 3Q24 | I17: Multi-family | J17: =E17 -> 41349 | K17: mn | L17: USD | M17: CRE
B18: Office | C18: 25946 | D18: 3050 | E18: =SUM(C18:D18) -> 28996 | G18: WFC | H18: 3Q24 | I18: Office | J18: =E18 -> 28996 | K18: mn | L18: USD | M18: CRE
B19: Industrial/warehouse | C19: 21147 | D19: 3456 | E19: =SUM(C19:D19) -> 24603 | G19: WFC | H19: 3Q24 | I19: Industrial | J19: =E19 -> 24603 | K19: mn | L19: USD | M19: CRE
B20: Retail (exc shopping center) | C20: 11303 | D20: 73 | E20: =SUM(C20:D20) -> 11376 | G20: WFC | H20: 3Q24 | I20: Retail | J20: =E20+E22 -> 19961 | K20: mn | L20: USD | M20: CRE
B21: Hotel/motel | C21: 10682 | D21: 783 | E21: =SUM(C21:D21) -> 11465 | G21: WFC | H21: 3Q24 | I21: Lodging | J21: =E21 -> 11465 | K21: mn | L21: USD | M21: CRE
B22: Shopping center | C22: 8311 | D22: 274 | E22: =SUM(C22:D22) -> 8585 | G22: WFC | H22: 3Q24 | I22: Mixed-use | J22: =E24 -> 2575 | K22: mn | L22: USD | M22: CRE
B23: Institutional | C23: 4245 | D23: 1148 | E23: =SUM(C23:D23) -> 5393 | G23: WFC | H23: 3Q24 | I23: Residential | J23: =E25 -> 1190 | K23: mn | L23: USD | M23: CRE
B24: Mixed use properties | C24: 2492 | D24: 83 | E24: =SUM(C24:D24) -> 2575 | G24: WFC | H24: 3Q24 | I24: Other | J24: =SUM(E26:E27,E23) -> 11271 | K24: mn | L24: USD | M24: CRE
B25: 1-4 family structure | C25: 0 | D25: 1190 | E25: =SUM(C25:D25) -> 1190 | G25: WFC | H25: 3Q24 | I25: Total CRE | J25: =SUM(J17:J24) -> 141410 | K25: mn | L25: USD | M25: CRE
B26: Storage facility | C26: 2038 | D26: 159 | E26: =SUM(C26:D26) -> 2197
B27: Other | C27: 3238 | D27: 443 | E27: =SUM(C27:D27) -> 3681
B28: Total CRE | C28: =SUM(C17:C27) -> 118776 | D28: =SUM(D17:D27) -> 22634 | E28: =SUM(E17:E27) -> 141410
A30: 2Q24 | B30: CRE Property Type | C30: CRE Mortgage | D30: CRE Construction | E30: Total | G30: Ticker | H30: Quarter | I30: CRE Property Type | J30: Loan Amount | K30: Unit | L30: Currency | M30: Category
B31: Apartments | C31: 31249 | D31: 11799 | E31: =SUM(C31:D31) -> 43048 | G31: WFC | H31: 2Q24 | I31: Multi-family | J31: =E31 -> 43048 | K31: mn | L31: USD | M31: CRE
B32: Office | C32: 26714 | D32: 2990 | E32: =SUM(C32:D32) -> 29704 | G32: WFC | H32: 2Q24 | I32: Office | J32: =E32 -> 29704 | K32: mn | L32: USD | M32: CRE
B33: Industrial/warehouse | C33: 21024 | D33: 3853 | E33: =SUM(C33:D33) -> 24877 | G33: WFC | H33: 2Q24 | I33: Industrial | J33: =E33 -> 24877 | K33: mn | L33: USD | M33: CRE
B34: Retail (excl shoppingcenter) | C34: 11193 | D34: 80 | E34: =SUM(C34:D34) -> 11273 | G34: WFC | H34: 2Q24 | I34: Retail | J34: =E34+E36 -> 19991 | K34: mn | L34: USD | M34: CRE
B35: Hotel/motel | C35: 10839 | D35: 762 | E35: =SUM(C35:D35) -> 11601 | G35: WFC | H35: 2Q24 | I35: Lodging | J35: =E35 -> 11601 | K35: mn | L35: USD | M35: CRE
B36: Shopping center | C36: 8402 | D36: 316 | E36: =SUM(C36:D36) -> 8718 | G36: WFC | H36: 2Q24 | I36: Mixed-use | J36: =E38 -> 2923 | K36: mn | L36: USD | M36: CRE
B37: Institutional | C37: 4323 | D37: 1232 | E37: =SUM(C37:D37) -> 5555 | G37: WFC | H37: 2Q24 | I37: Residential | J37: =E40 -> 1143 | K37: mn | L37: USD | M37: CRE
B38: Mixed use properties | C38: 2877 | D38: 46 | E38: =SUM(C38:D38) -> 2923 | G38: WFC | H38: 2Q24 | I38: Other | J38: =SUM(E39,E37,E41) -> 12031 | K38: mn | L38: USD | M38: CRE
B39: Storage facility | C39: 2194 | D39: 151 | E39: =SUM(C39:D39) -> 2345 | G39: WFC | H39: 2Q24 | I39: Total CRE | J39: =SUM(J31:J38) -> 145318 | K39: mn | L39: USD | M39: CRE
B40: 1-4 family structure | C40: — | D40: 1143 | E40: =SUM(C40:D40) -> 1143
B41: Other | C41: 3718 | D41: 413 | E41: =SUM(C41:D41) -> 4131
B42: Total CRE | C42: =SUM(C31:C41) -> 122533 | D42: =SUM(D31:D41) -> 22785 | E42: =SUM(E31:E41) -> 145318
A44: 1Q24 | B44: CRE Property Type | C44: CRE Mortgage | D44: CRE Construction | E44: Total | G44: Ticker | H44: Quarter | I44: CRE Property Type | J44: Loan Amount | K44: Unit | L44: Currency | M44: Category
...

Sheet WFC LLM API
B2: 4Q24 AI API Script
B18: Correct
B20: CRE Property Type | C20: Total
B21: Apartments | C21: 39758
B22: Office | C22: 27380
B23: Industrial/warehouse | C23: 24038
B24: Hotel/motel | C24: 11506
B25: Retail (excl shoppingcenter) | C25: 11345
B26: Shopping center | C26: 8113
B27: Institutional | C27: 5186
B28: Mixed use properties | C28: 2316
B29: Mobile home park | C29: 2273
B30: Storage facility | C30: 2088
B31: Other | C31: 2502
B32: Total CRE | C32: 136505
B34: Correct | E34: LLM
B36: CRE Property Type | C36: Loan Amount | E36: CRE Property Type | F36: Loan Amount | H36: =B36=E36 -> TRUE | I36: =C36=F36 -> TRUE
B37: Multi-family | C37: =C21 -> 39758 | E37: Multi-family | F37: 39758 | H37: =B37=E37 -> TRUE | I37: =C37=F37 -> TRUE
B38: Office | C38: =C22 -> 27380 | E38: Office | F38: 27380 | H38: =B38=E38 -> TRUE | I38: =C38=F38 -> TRUE
B39: Industrial | C39: =C23 -> 24038 | E39: Industrial | F39: 24038 | H39: =B39=E39 -> TRUE | I39: =C39=F39 -> TRUE
